<?xml version="1.0" ?>
<!-- =================================================================================== -->
<!-- |    This document was autogenerated by xacro from p26_lefty.xacro                | -->
<!-- |    EDITING THIS FILE BY HAND IS NOT RECOMMENDED                                 | -->
<!-- =================================================================================== -->
<robot name="p26_lefty" xmlns:xacro="http://ros.org/wiki/xacro">
  <!--  <xacro:property name="prefix" value="" />-->
  <!-- Conversion were obtained from http://www.e-paint.co.uk/Lab_values.asp
       unless otherwise stated. -->
  <!-- link list -->
  <link name="lefty_track_left">
    <!--track_start-->
    <visual>
      <origin rpy="0 0 0" xyz="0 0 0"/>
      <geometry>
        <mesh filename="package://abb_irbt4004_support/meshes/irbt4004/visual/Track_Start.stl"/>
      </geometry>
      <material name="">
        <color rgba="0.7372549 0.3490196 0.1607843 1"/>
      </material>
    </visual>
    <collision>
      <origin rpy="0 0 0" xyz="0 0 0"/>
      <geometry>
        <mesh filename="package://abb_irbt4004_support/meshes/irbt4004/collision/Track_Start.stl"/>
      </geometry>
      <material name="">
        <color rgba="0.7372549 0.3490196 0.1607843 1"/>
      </material>
    </collision>
  </link>
  <link name="lefty_track_mid_1">
    <visual>
      <origin rpy="0 0 0" xyz="0 0 0"/>
      <geometry>
        <mesh filename="package://abb_irbt4004_support/meshes/irbt4004/visual/Track_Mid.stl"/>
      </geometry>
      <material name="">
        <color rgba="0.7372549 0.3490196 0.1607843 1"/>
      </material>
    </visual>
    <collision>
      <origin rpy="0 0 0" xyz="0 0 0"/>
      <geometry>
        <mesh filename="package://abb_irbt4004_support/meshes/irbt4004/collision/Track_Mid.stl"/>
      </geometry>
      <material name="">
        <color rgba="0.7372549 0.3490196 0.1607843 1"/>
      </material>
    </collision>
  </link>
  <link name="lefty_track_mid_2">
    <visual>
      <origin rpy="0 0 0" xyz="0 0 0"/>
      <geometry>
        <mesh filename="package://abb_irbt4004_support/meshes/irbt4004/visual/Track_Mid.stl"/>
      </geometry>
      <material name="">
        <color rgba="0.7372549 0.3490196 0.1607843 1"/>
      </material>
    </visual>
    <collision>
      <origin rpy="0 0 0" xyz="0 0 0"/>
      <geometry>
        <mesh filename="package://abb_irbt4004_support/meshes/irbt4004/collision/Track_Mid.stl"/>
      </geometry>
      <material name="">
        <color rgba="0.7372549 0.3490196 0.1607843 1"/>
      </material>
    </collision>
  </link>
  <link name="lefty_track_mid_3">
    <visual>
      <origin rpy="0 0 0" xyz="0 0 0"/>
      <geometry>
        <mesh filename="package://abb_irbt4004_support/meshes/irbt4004/visual/Track_Mid.stl"/>
      </geometry>
      <material name="">
        <color rgba="0.7372549 0.3490196 0.1607843 1"/>
      </material>
    </visual>
    <collision>
      <origin rpy="0 0 0" xyz="0 0 0"/>
      <geometry>
        <mesh filename="package://abb_irbt4004_support/meshes/irbt4004/collision/Track_Mid.stl"/>
      </geometry>
      <material name="">
        <color rgba="0.7372549 0.3490196 0.1607843 1"/>
      </material>
    </collision>
  </link>
  <!--Right section-->
  <!--<link name="${prefix}track_right">
      <visual>
        <origin xyz="0 0 0" rpy="0 0 0"/>
        <geometry>
          <mesh filename="package://abb_irbt4004_support/meshes/irbt4004/visual/Track_End.stl"/>
        </geometry>
        <xacro:material_abb_orange />
      </visual>
      <collision>
        <origin xyz="0 0 0" rpy="0 0 0"/>
        <geometry>
          <mesh filename="package://abb_irbt4004_support/meshes/irbt4004/collision/Track_End.stl"/>
        </geometry>
        <xacro:material_abb_orange />
      </collision>
    </link>-->
  <!--Left carriage-->
  <link name="lefty_carriage">
    <visual>
      <origin rpy="0 0 0" xyz="0 0 0"/>
      <geometry>
        <mesh filename="package://abb_irbt4004_support/meshes/irbt4004/visual/Carriage_left.stl"/>
      </geometry>
      <material name="">
        <color rgba="0.3450980 0.3647059 0.3686275 1"/>
      </material>
    </visual>
    <collision>
      <origin rpy="0 0 0" xyz="0 0 0"/>
      <geometry>
        <mesh filename="package://abb_irbt4004_support/meshes/irbt4004/collision/Carriage_left.stl"/>
      </geometry>
      <material name="">
        <color rgba="0.3450980 0.3647059 0.3686275 1"/>
      </material>
    </collision>
  </link>
  <link name="lefty_belt_collision">
    <collision>
      <origin rpy="0 0 0" xyz="1.85 -0.20 0.3"/>
      <geometry>
        <box size="5.80 0.40 0.6"/>
      </geometry>
      <material name="">
        <color rgba="0.3450980 0.3647059 0.3686275 1"/>
      </material>
    </collision>
  </link>
  <link name="lefty_belt_loop">
    <visual>
      <origin rpy="0 0 0" xyz="0 0 0"/>
      <geometry>
        <mesh filename="package://abb_irbt4004_support/meshes/irbt4004/visual/Belt_left_loop.stl"/>
      </geometry>
      <material name="">
        <color rgba="0.3450980 0.3647059 0.3686275 1"/>
      </material>
    </visual>
    <!--      <collision>
        <origin xyz="0 0 0" rpy="0 0 0"/>
        <geometry>
          <mesh filename="package://abb_irbt4004_support/meshes/irbt4004/collision/Belt_left_loop.stl"/>
        </geometry>
        <xacro:material_abb_dark_gray />
      </collision>-->
  </link>
  <link name="lefty_belt_0">
    <visual>
      <origin rpy="0 0 0" xyz="0 0 0"/>
      <geometry>
        <mesh filename="package://abb_irbt4004_support/meshes/irbt4004/visual/Belt_left_ext.stl"/>
      </geometry>
      <material name="">
        <color rgba="0.3450980 0.3647059 0.3686275 1"/>
      </material>
    </visual>
    <!--      <collision>
        <origin xyz="0 0 0" rpy="0 0 0"/>
        <geometry>
          <mesh filename="package://abb_irbt4004_support/meshes/irbt4004/collision/Belt_left_ext.stl"/>
        </geometry>
        <xacro:material_abb_dark_gray />
      </collision>-->
  </link>
  <link name="lefty_belt_1">
    <visual>
      <origin rpy="0 0 0" xyz="0 0 0"/>
      <geometry>
        <mesh filename="package://abb_irbt4004_support/meshes/irbt4004/visual/Belt_left_ext.stl"/>
      </geometry>
      <material name="">
        <color rgba="0.3450980 0.3647059 0.3686275 1"/>
      </material>
    </visual>
    <!--      <collision>
        <origin xyz="0 0 0" rpy="0 0 0"/>
        <geometry>
          <mesh filename="package://abb_irbt4004_support/meshes/irbt4004/collision/Belt_left_ext.stl"/>
        </geometry>
        <xacro:material_abb_dark_gray />
      </collision>-->
  </link>
  <link name="lefty_belt_2">
    <visual>
      <origin rpy="0 0 0" xyz="0 0 0"/>
      <geometry>
        <mesh filename="package://abb_irbt4004_support/meshes/irbt4004/visual/Belt_left_ext.stl"/>
      </geometry>
      <material name="">
        <color rgba="0.3450980 0.3647059 0.3686275 1"/>
      </material>
    </visual>
    <!--      <collision>
        <origin xyz="0 0 0" rpy="0 0 0"/>
        <geometry>
          <mesh filename="package://abb_irbt4004_support/meshes/irbt4004/collision/Belt_left_ext.stl"/>
        </geometry>
        <xacro:material_abb_dark_gray />
      </collision>-->
  </link>
  <link name="lefty_belt_3">
    <visual>
      <origin rpy="0 0 0" xyz="0 0 0"/>
      <geometry>
        <mesh filename="package://abb_irbt4004_support/meshes/irbt4004/visual/Belt_left_ext.stl"/>
      </geometry>
      <material name="">
        <color rgba="0.3450980 0.3647059 0.3686275 1"/>
      </material>
    </visual>
    <!--      <collision>
        <origin xyz="0 0 0" rpy="0 0 0"/>
        <geometry>
          <mesh filename="package://abb_irbt4004_support/meshes/irbt4004/collision/Belt_left_ext.stl"/>
        </geometry>
        <xacro:material_abb_dark_gray />
      </collision>-->
  </link>
  <link name="lefty_belt_4">
    <visual>
      <origin rpy="0 0 0" xyz="0 0 0"/>
      <geometry>
        <mesh filename="package://abb_irbt4004_support/meshes/irbt4004/visual/Belt_left_ext.stl"/>
      </geometry>
      <material name="">
        <color rgba="0.3450980 0.3647059 0.3686275 1"/>
      </material>
    </visual>
    <!--      <collision>
        <origin xyz="0 0 0" rpy="0 0 0"/>
        <geometry>
          <mesh filename="package://abb_irbt4004_support/meshes/irbt4004/collision/Belt_left_ext.stl"/>
        </geometry>
        <xacro:material_abb_dark_gray />
      </collision>-->
  </link>
  <!--Right carriage-->
  <!--<link name="${prefix}carriage2">
      <visual>
      <origin xyz="0 0 0" rpy="0 0 0"/>
        <geometry>
          <mesh filename="package://abb_irbt4004_support/meshes/irbt4004/visual/Carriage_right.stl"/>
        </geometry>
        <xacro:material_abb_dark_gray />
      </visual>
      <collision>
        <origin xyz="0 0 0" rpy="0 0 0"/>
        <geometry>
          <mesh filename="package://abb_irbt4004_support/meshes/irbt4004/collision/Carriage_right.stl"/>
        </geometry>
        <xacro:material_abb_dark_gray />
      </collision>
    </link>-->
  <link name="lefty_carriage_interface"/>
  <!-- end of link list -->
  <!-- joint list -->
  <joint name="lefty_fixed_track_mid_1" type="fixed">
    <parent link="lefty_track_left"/>
    <child link="lefty_track_mid_1"/>
    <origin rpy="0 0 0" xyz="0.000 0.000 0.000"/>
  </joint>
  <joint name="lefty_fixed_track_mid_2" type="fixed">
    <parent link="lefty_track_mid_1"/>
    <child link="lefty_track_mid_2"/>
    <origin rpy="0 0 0" xyz="1.000 0.000 0.000"/>
  </joint>
  <joint name="lefty_fixed_track_mid_3" type="fixed">
    <parent link="lefty_track_mid_2"/>
    <child link="lefty_track_mid_3"/>
    <origin rpy="0 0 0" xyz="1.000 0.000 0.000"/>
  </joint>
  <!--Track end-->
  <!--<joint name="${prefix}fixed_track_right" type="fixed">
      <parent link="${prefix}track_mid_3"/>
      <child link="${prefix}track_right"/>
      <origin xyz="1.000 0.000 0.000" rpy="0 0 0"/>
    </joint>-->
  <!--carriage-->
  <joint name="lefty_joint_carriage" type="prismatic">
    <parent link="lefty_track_left"/>
    <child link="lefty_carriage"/>
    <origin rpy="0 0 0" xyz="0 0 0"/>
    <axis xyz="1 0 0"/>
    <limit effort="0" lower="0.000" upper="3.900" velocity="2.000"/>
    <!-- Product specification - IRBT 4004/6004/7004 -->
  </joint>
  <joint name="lefty_joint_belt_collision" type="fixed">
    <parent link="lefty_track_left"/>
    <child link="lefty_belt_collision"/>
    <origin rpy="0 0 0" xyz="0 0 0"/>
  </joint>
  <joint name="lefty_joint_belt_loop" type="prismatic">
    <parent link="lefty_track_left"/>
    <child link="lefty_belt_loop"/>
    <origin rpy="0 0 0" xyz="0.35 0 0"/>
    <axis xyz="1 0 0"/>
    <limit effort="0" lower="0.000" upper="3.900" velocity="2.000"/>
    <mimic joint="lefty_joint_carriage" multiplier="0.5"/>
  </joint>
  <joint name="lefty_joint_belt_0" type="prismatic">
    <parent link="lefty_track_left"/>
    <child link="lefty_belt_0"/>
    <origin rpy="0 0 0" xyz="0 0 0"/>
    <axis xyz="1 0 0"/>
    <limit effort="0" lower="0.000" upper="3.900" velocity="2.000"/>
    <mimic joint="lefty_joint_carriage" multiplier="0.5"/>
  </joint>
  <joint name="lefty_joint_belt_1" type="prismatic">
    <parent link="lefty_track_left"/>
    <child link="lefty_belt_1"/>
    <origin rpy="0 0 0" xyz="0 0 0"/>
    <axis xyz="1 0 0"/>
    <limit effort="0" lower="0.000" upper="3.900" velocity="2.000"/>
    <mimic joint="lefty_joint_carriage" multiplier="0.625"/>
  </joint>
  <joint name="lefty_joint_belt_2" type="prismatic">
    <parent link="lefty_track_left"/>
    <child link="lefty_belt_2"/>
    <origin rpy="0 0 0" xyz="0 0 0"/>
    <axis xyz="1 0 0"/>
    <limit effort="0" lower="0.000" upper="3.900" velocity="2.000"/>
    <mimic joint="lefty_joint_carriage" multiplier="0.75"/>
  </joint>
  <joint name="lefty_joint_belt_3" type="prismatic">
    <parent link="lefty_track_left"/>
    <child link="lefty_belt_3"/>
    <origin rpy="0 0 0" xyz="0 0 0"/>
    <axis xyz="1 0 0"/>
    <limit effort="0" lower="0.000" upper="3.900" velocity="2.000"/>
    <mimic joint="lefty_joint_carriage" multiplier="0.875"/>
  </joint>
  <joint name="lefty_joint_belt_4" type="prismatic">
    <parent link="lefty_track_left"/>
    <child link="lefty_belt_4"/>
    <origin rpy="0 0 0" xyz="0 0 0"/>
    <axis xyz="1 0 0"/>
    <limit effort="0" lower="0.500" upper="3.900" velocity="2.000"/>
    <mimic joint="lefty_joint_carriage" multiplier="1.0"/>
  </joint>
  <!-- Robot interface point -->
  <joint name="lefty_carriage_interface_link" type="fixed">
    <parent link="lefty_carriage"/>
    <child link="lefty_carriage_interface"/>
    <origin rpy="0 0 1.57079632" xyz="0.3955 0.560 0.3745"/>
    <!-- 650-254=396 -->
  </joint>
  <!--          <origin xyz="0.3955 0.560 0.3745" rpy="0 0 1.57079632" />-->
  <!-- end of joint list -->
  <!-- Connecting irbt carriage to irb base-link -->
  <joint name="lefty_robot_interface_link" type="fixed">
    <parent link="lefty_carriage_interface"/>
    <child link="lefty_base_link"/>
    <origin rpy="0 0 0" xyz="0 0 0"/>
  </joint>
  --&gt;

  
  <!-- Conversion were obtained from http://www.e-paint.co.uk/Lab_values.asp
       unless otherwise stated. -->
  <!-- link list -->
  <link name="lefty_base_link">
    <visual>
      <origin rpy="0 0 0" xyz="0 0 0"/>
      <geometry>
        <mesh filename="package://abb_irb4400_support/meshes/irb4400_60/visual/base_link.stl"/>
      </geometry>
      <material name="">
        <color rgba="0.7372549 0.3490196 0.1607843 1"/>
      </material>
    </visual>
    <collision>
      <geometry>
        <mesh filename="package://abb_irb4400_support/meshes/irb4400_60/collision/base_link.stl"/>
      </geometry>
      <material name="">
        <color rgba="1 1 0 1"/>
      </material>
    </collision>
  </link>
  <link name="lefty_link_1">
    <visual>
      <origin rpy="0 0 0" xyz="0 0 0"/>
      <geometry>
        <mesh filename="package://abb_irb4400_support/meshes/irb4400_60/visual/link_1.stl"/>
      </geometry>
      <material name="">
        <color rgba="0.7372549 0.3490196 0.1607843 1"/>
      </material>
    </visual>
    <collision>
      <origin rpy="0 0 0" xyz="0 0 0"/>
      <geometry>
        <mesh filename="package://abb_irb4400_support/meshes/irb4400_60/collision/link_1.stl"/>
      </geometry>
      <material name="">
        <color rgba="1 1 0 1"/>
      </material>
    </collision>
  </link>
  <link name="lefty_link_2">
    <visual>
      <origin rpy="0 0 0" xyz="0 0 0"/>
      <geometry>
        <mesh filename="package://abb_irb4400_support/meshes/irb4400_60/visual/link_2.stl"/>
      </geometry>
      <material name="">
        <color rgba="0.7372549 0.3490196 0.1607843 1"/>
      </material>
    </visual>
    <collision>
      <origin rpy="0 0 0" xyz="0 0 0"/>
      <geometry>
        <mesh filename="package://abb_irb4400_support/meshes/irb4400_60/collision/link_2.stl"/>
      </geometry>
      <material name="">
        <color rgba="1 1 0 1"/>
      </material>
    </collision>
  </link>
  <link name="lefty_link_3">
    <visual>
      <origin rpy="0 0 0" xyz="0 0 0"/>
      <geometry>
        <mesh filename="package://abb_irb4400_support/meshes/irb4400_60/visual/link_3.stl"/>
      </geometry>
      <material name="">
        <color rgba="0.7372549 0.3490196 0.1607843 1"/>
      </material>
    </visual>
    <collision>
      <origin rpy="0 0 0" xyz="0 0 0"/>
      <geometry>
        <mesh filename="package://abb_irb4400_support/meshes/irb4400_60/collision/link_3.stl"/>
      </geometry>
      <material name="">
        <color rgba="1 1 0 1"/>
      </material>
    </collision>
  </link>
  <link name="lefty_link_4">
    <visual>
      <origin rpy="0 0 0" xyz="0 0 0"/>
      <geometry>
        <mesh filename="package://abb_irb4400_support/meshes/irb4400_60/visual/link_4.stl"/>
      </geometry>
      <material name="">
        <color rgba="0.7372549 0.3490196 0.1607843 1"/>
      </material>
    </visual>
    <collision>
      <origin rpy="0 0 0" xyz="0 0 0"/>
      <geometry>
        <mesh filename="package://abb_irb4400_support/meshes/irb4400_60/collision/link_4.stl"/>
      </geometry>
      <material name="">
        <color rgba="1 1 0 1"/>
      </material>
    </collision>
  </link>
  <link name="lefty_link_5">
    <visual>
      <origin rpy="0 0 0" xyz="0 0 0"/>
      <geometry>
        <mesh filename="package://abb_irb4400_support/meshes/irb4400_60/visual/link_5.stl"/>
      </geometry>
      <material name="">
        <color rgba="0.7372549 0.3490196 0.1607843 1"/>
      </material>
    </visual>
    <collision>
      <origin rpy="0 0 0" xyz="0 0 0"/>
      <geometry>
        <mesh filename="package://abb_irb4400_support/meshes/irb4400_60/collision/link_5.stl"/>
      </geometry>
      <material name="">
        <color rgba="1 1 0 1"/>
      </material>
    </collision>
  </link>
  <link name="lefty_link_6">
    <visual>
      <origin rpy="0 0 0" xyz="0 0 0"/>
      <geometry>
        <mesh filename="package://abb_irb4400_support/meshes/irb4400_60/visual/link_6.stl"/>
      </geometry>
      <material name="">
        <color rgba="0.1882353 0.1960784 0.2039216 1"/>
      </material>
    </visual>
    <collision>
      <origin rpy="0 0 0" xyz="0 0 0"/>
      <geometry>
        <mesh filename="package://abb_irb4400_support/meshes/irb4400_60/collision/link_6.stl"/>
      </geometry>
      <material name="">
        <color rgba="1 1 0 1"/>
      </material>
    </collision>
  </link>
  <link name="lefty_link_d1">
    <visual>
      <origin rpy="0 0 0" xyz="0 0 0"/>
      <geometry>
        <mesh filename="package://abb_irb4400_support/meshes/irb4400_60/visual/link_d1.stl"/>
      </geometry>
      <material name="">
        <color rgba="0.7372549 0.3490196 0.1607843 1"/>
      </material>
    </visual>
    <collision>
      <origin rpy="0 0 0" xyz="0 0 0"/>
      <geometry>
        <mesh filename="package://abb_irb4400_support/meshes/irb4400_60/collision/link_d1.stl"/>
      </geometry>
      <material name="">
        <color rgba="1 1 0 1"/>
      </material>
    </collision>
  </link>
  <link name="lefty_link_d2">
    <visual>
      <origin rpy="0 0 0" xyz="0 0 0"/>
      <geometry>
        <mesh filename="package://abb_irb4400_support/meshes/irb4400_60/visual/link_d2.stl"/>
      </geometry>
      <material name="">
        <color rgba="0.7372549 0.3490196 0.1607843 1"/>
      </material>
    </visual>
    <collision>
      <origin rpy="0 0 0" xyz="0 0 0"/>
      <geometry>
        <mesh filename="package://abb_irb4400_support/meshes/irb4400_60/collision/link_d2.stl"/>
      </geometry>
      <material name="">
        <color rgba="1 1 0 1"/>
      </material>
    </collision>
  </link>
  <link name="lefty_tool0"/>
  <!-- end of link list -->
  <!-- joint list -->
  <joint name="lefty_joint_1" type="revolute">
    <origin rpy="0 0 0" xyz="0 0 0"/>
    <parent link="lefty_base_link"/>
    <child link="lefty_link_1"/>
    <axis xyz="0 0 1"/>
    <limit effort="0" lower="-2.87979" upper="2.87979" velocity="2.618"/>
  </joint>
  <joint name="lefty_joint_2" type="revolute">
    <origin rpy="0 0 0" xyz="0.2 0 0.68"/>
    <parent link="lefty_link_1"/>
    <child link="lefty_link_2"/>
    <axis xyz="0 1 0"/>
    <limit effort="0" lower="-1.2217" upper="1.658" velocity="2.0944"/>
  </joint>
  <joint name="lefty_joint_3" type="revolute">
    <origin rpy="0 0 0" xyz="0 0 0.89"/>
    <parent link="lefty_link_2"/>
    <child link="lefty_link_3"/>
    <axis xyz="0 1 0"/>
    <limit effort="0" lower="-0.2" upper="1.1345" velocity="2.0944"/>
    <!--less than robotstudio to avoid out of range-->
    <!--      <limit effort="0" lower="-0.523599" upper="1.1345" velocity="2.0944"/>-->
    <!--robotstudio-->
    <!--      <limit effort="0" lower="-1.0472" upper="1.1345" velocity="2.0944"/> -->
  </joint>
  <joint name="lefty_joint_4" type="revolute">
    <!--  <origin xyz="1.38 0 0.15" rpy="0 0 0"/> IRB4400/L10-->
    <origin rpy="0 0 0" xyz="0.880 0 0.15"/>
    <!-- IRB4400/60-->
    <parent link="lefty_link_3"/>
    <child link="lefty_link_4"/>
    <axis xyz="1 0 0"/>
    <limit effort="0" lower="-3.49" upper="3.49" velocity="3.927"/>
  </joint>
  <joint name="lefty_joint_5" type="revolute">
    <origin rpy="0 0 0" xyz="0 0 0"/>
    <parent link="lefty_link_4"/>
    <child link="lefty_link_5"/>
    <axis xyz="0 1 0"/>
    <limit effort="0" lower="-2.0944" upper="2.0944" velocity="4.3633"/>
  </joint>
  <joint name="lefty_joint_6" type="revolute">
    <origin rpy="0 0 0" xyz="0 0 0"/>
    <parent link="lefty_link_5"/>
    <child link="lefty_link_6"/>
    <axis xyz="1 0 0"/>
    <limit effort="0" lower="-3.1415" upper="3.1415" velocity="5.7596"/>
    <!--reduced to 180deg-->
    <!--      <limit effort="0" lower="-6.9813" upper="6.9813" velocity="5.7596"/>-->
    <!--spec-->
  </joint>
  <joint name="lefty_joint_6-tool0" type="fixed">
    <parent link="lefty_link_6"/>
    <child link="lefty_tool0"/>
    <origin rpy="0 0 0" xyz="0.14 0 0"/>
  </joint>
  <joint name="lefty_joint_d2" type="continuous">
    <origin rpy="0 0 0" xyz="0 0 0"/>
    <axis xyz="0 1 0"/>
    <parent link="lefty_link_2"/>
    <child link="lefty_link_d2"/>
    <mimic joint="lefty_joint_3" multiplier="1.0"/>
  </joint>
  <joint name="lefty_joint_d1" type="continuous">
    <origin rpy="0 0 0" xyz="-0.3 0 0"/>
    <axis xyz="0 1 0"/>
    <parent link="lefty_link_d2"/>
    <child link="lefty_link_d1"/>
    <mimic joint="lefty_joint_3" multiplier="-1.0"/>
  </joint>
  <!-- end of joint list -->
  <!-- ROS base_link to ABB World Coordinates transform -->
  <link name="lefty_base"/>
  <joint name="lefty_base_link-base" type="fixed">
    <origin rpy="0 0 0" xyz="0 0 0"/>
    <parent link="lefty_base_link"/>
    <child link="lefty_base"/>
  </joint>
  <!--Tool-->
  <link name="lefty_tool">
    <visual>
      <origin rpy="0 -1.57079632 0" xyz="0.03 -0.0625 -0.1"/>
      <geometry>
        <mesh filename="package://p26_robot/meshes/tool0/visual/tool0.STL" scale="0.001 0.001 0.001"/>
      </geometry>
      <material name="">
        <color rgba="0.9254902 0.9254902 0.9058824 1"/>
      </material>
    </visual>
    <collision>
      <origin rpy="0 -1.57079632 0" xyz="0.03 -0.0625 -0.1"/>
      <geometry>
        <mesh filename="package://p26_robot/meshes/tool0/collision/tool0.STL" scale="0.001 0.001 0.001"/>
      </geometry>
      <material name="">
        <color rgba="0.9254902 0.9254902 0.9058824 1"/>
      </material>
    </collision>
  </link>
  <joint name="lefty_tool" type="fixed">
    <parent link="lefty_tool0"/>
    <child link="lefty_tool"/>
    <origin rpy="0 0 0" xyz="0 0 0"/>
  </joint>
  <!-- Insert point must be defined by a fixed joint-->
  <link name="world"/>
  <joint name="lefty_offset" type="fixed">
    <parent link="world"/>
    <child link="lefty_track_left"/>
    <origin rpy="0 0 1.57079632" xyz="7.000 3.6645 0.000"/>
  </joint>
</robot>

